Workbook
Name Slicer_Category: #N/A
Name Slicer_City: #N/A
Name Slicer_Month: #N/A
Name Slicer_Product: #N/A

Sheet Dateset
A1: OrderID | B1: OrderDate | C1: CustomerName | D1: City | E1: Product | F1: Category | G1: Quantity | H1: Price | I1: Discount | J1: Sales | K1: Month | L1: Distinct Count | N1: Sorted By Category | Q1: Product | R1: Quantity
A2: 1001 | B2: 05-05-2024 | C2: Sanjay | D2: Bangalore | E2: Phone | F2: Electronics | G2: 1 | H2: 20000 | I2: 0.1 | J2: =H2*(1-I2)*G2 -> 18000 | K2: =TEXT(Table4[OrderDate], "mmmm") -> May | L2: =IF(C2 = "", 0, IF(COUNTIF($C$2:C2, C2) = 1, 1, 0)) -> 1 | N2: Electronics | O2: 40606300 | Q2: Phone | R2: 427
A3: 1043 | B3: 05-04-2024 | C3: Neha | D3: Mumbai | E3: Laptop | F3: Electronics | G3: 5 | H3: 50000 | I3: 0 | J3: =H3*(1-I3)*G3 -> 250000 | K3: =TEXT(Table4[OrderDate], "mmmm") -> April | L3: =IF(C3 = "", 0, IF(COUNTIF($C$2:C3, C3) = 1, 1, 0)) -> 1 | N3: Furniture | O3: 3117100 | Q3: Keyboard | R3: 410
A4: 1003 | B4: 29-04-2024 | C4: Ravi | D4: Lucknow | E4: Laptop | F4: Electronics | G4: 1 | H4: 50000 | I4: 0.05 | J4: =H4*(1-I4)*G4 -> 47500 | K4: =TEXT(Table4[OrderDate], "mmmm") -> April | L4: =IF(C4 = "", 0, IF(COUNTIF($C$2:C4, C4) = 1, 1, 0)) -> 1 | N4: Accessories | O4: 1229575 | Q4: Tablet | R4: 404
A5: 1004 | B5: 28-10-2024 | C5: Pooja | D5: Delhi | E5: Keyboard | F5: Accessories | G5: 2 | H5: 1500 | I5: 0.15 | J5: =H5*(1-I5)*G5 -> 2550 | K5: =TEXT(Table4[OrderDate], "mmmm") -> October | L5: =IF(C5 = "", 0, IF(COUNTIF($C$2:C5, C5) = 1, 1, 0)) -> 1 | Q5: Laptop | R5: 378
A6: 1005 | B6: 22-05-2024 | C6: Karan | D6: Lucknow | E6: Tablet | F6: Electronics | G6: 4 | H6: 30000 | I6: 0.1 | J6: =H6*(1-I6)*G6 -> 108000 | K6: =TEXT(Table4[OrderDate], "mmmm") -> May | L6: =IF(C6 = "", 0, IF(COUNTIF($C$2:C6, C6) = 1, 1, 0)) -> 1 | N6: Electronics Sales | Q6: Monitor | R6: 370
A7: 1006 | B7: 13-07-2024 | C7: Priya | D7: Pune | E7: Headphones | F7: Accessories | G7: 1 | H7: 2000 | I7: 0 | J7: =H7*(1-I7)*G7 -> 2000 | K7: =TEXT(Table4[OrderDate], "mmmm") -> July | L7: =IF(C7 = "", 0, IF(COUNTIF($C$2:C7, C7) = 1, 1, 0)) -> 1 | N7: Electronics | O7: =SUMIF(F2:F1001, N7, J2:J1001) -> 40606300 | Q7: Headphones | R7: 359
A8: 1094 | B8: 28-06-2024 | C8: Sanjay | D8: Mumbai | E8: Laptop | F8: Electronics | G8: 5 | H8: 50000 | I8: 0 | J8: =H8*(1-I8)*G8 -> 250000 | K8: =TEXT(Table4[OrderDate], "mmmm") -> June | L8: =IF(C8 = "", 0, IF(COUNTIF($C$2:C8, C8) = 1, 1, 0)) -> 0 | Q8: Chair | R8: 357
A9: 1008 | B9: 17-11-2024 | C9: Sneha | D9: Lucknow | E9: Keyboard | F9: Accessories | G9: 1 | H9: 1500 | I9: 0.1 | J9: =H9*(1-I9)*G9 -> 1350 | K9: =TEXT(Table4[OrderDate], "mmmm") -> November | L9: =IF(C9 = "", 0, IF(COUNTIF($C$2:C9, C9) = 1, 1, 0)) -> 1 | N9: Average Order Value | O9: =AVERAGE(J2:J1001) -> 44952.975 | Q9: Table | R9: 329
A10: 1009 | B10: 28-05-2024 | C10: Neha | D10: Lucknow | E10: Phone | F10: Electronics | G10: 1 | H10: 20000 | I10: 0.05 | J10: =H10*(1-I10)*G10 -> 19000 | K10: =TEXT(Table4[OrderDate], "mmmm") -> May | L10: =IF(C10 = "", 0, IF(COUNTIF($C$2:C10, C10) = 1, 1, 0)) -> 0
A11: 1010 | B11: 20-08-2024 | C11: Sneha | D11: Bangalore | E11: Phone | F11: Electronics | G11: 4 | H11: 20000 | I11: 0.1 | J11: =H11*(1-I11)*G11 -> 72000 | K11: =TEXT(Table4[OrderDate], "mmmm") -> August | L11: =IF(C11 = "", 0, IF(COUNTIF($C$2:C11, C11) = 1, 1, 0)) -> 0 | N11: Average Discount Valus | O11: =ROUND(AVERAGE(Table4[Discount])*100, 2)&"%" -> 7.72% | Q11: Product | R11: Sales
A12: 1011 | B12: 09-12-2024 | C12: Pooja | D12: Mumbai | E12: Headphones | F12: Accessories | G12: 3 | H12: 2000 | I12: 0.05 | J12: =H12*(1-I12)*G12 -> 5700 | K12: =TEXT(Table4[OrderDate], "mmmm") -> December | L12: =IF(C12 = "", 0, IF(COUNTIF($C$2:C12, C12) = 1, 1, 0)) -> 0 | Q12: Phone | R12: =SUMIF(Table4[Product], Q12, Table4[Sales]) -> 7932000
A13: 1123 | B13: 16-04-2024 | C13: Anjali | D13: Jaipur | E13: Laptop | F13: Electronics | G13: 5 | H13: 50000 | I13: 0 | J13: =H13*(1-I13)*G13 -> 250000 | K13: =TEXT(Table4[OrderDate], "mmmm") -> April | L13: =IF(C13 = "", 0, IF(COUNTIF($C$2:C13, C13) = 1, 1, 0)) -> 1 | Q13: Keyboard | R13: =SUMIF(Table4[Product], Q13, Table4[Sales]) -> 569475
A14: 1646 | B14: 18-08-2024 | C14: Manish | D14: Bangalore | E14: Laptop | F14: Electronics | G14: 5 | H14: 50000 | I14: 0 | J14: =H14*(1-I14)*G14 -> 250000 | K14: =TEXT(Table4[OrderDate], "mmmm") -> August | L14: =IF(C14 = "", 0, IF(COUNTIF($C$2:C14, C14) = 1, 1, 0)) -> 1 | N14: Laptop | O14: =SUMIF(Table4[Product], N14, Table4[Sales]) -> 17447500 | Q14: Tablet | R14: =SUMIF(Table4[Product], Q14, Table4[Sales]) -> 11145000
A15: 1014 | B15: 24-07-2024 | C15: Pooja | D15: Mumbai | E15: Chair | F15: Furniture | G15: 1 | H15: 3000 | I15: 0.1 | J15: =H15*(1-I15)*G15 -> 2700 | K15: =TEXT(Table4[OrderDate], "mmmm") -> July | L15: =IF(C15 = "", 0, IF(COUNTIF($C$2:C15, C15) = 1, 1, 0)) -> 0 | Q15: Laptop | R15: =SUMIF(Table4[Product], Q15, Table4[Sales]) -> 17447500
A16: 1655 | B16: 13-01-2024 | C16: Arjun | D16: Bangalore | E16: Laptop | F16: Electronics | G16: 5 | H16: 50000 | I16: 0 | J16: =H16*(1-I16)*G16 -> 250000 | K16: =TEXT(Table4[OrderDate], "mmmm") -> January | L16: =IF(C16 = "", 0, IF(COUNTIF($C$2:C16, C16) = 1, 1, 0)) -> 1 | N16: Category Name | O16: Aveage | Q16: Monitor | R16: =SUMIF(Table4[Product], Q16, Table4[Sales]) -> 4081800
A17: 1016 | B17: 12-03-2024 | C17: Sanjay | D17: Jaipur | E17: Monitor | F17: Electronics | G17: 2 | H17: 12000 | I17: 0.1 | J17: =H17*(1-I17)*G17 -> 21600 | K17: =TEXT(Table4[OrderDate], "mmmm") -> March | L17: =IF(C17 = "", 0, IF(COUNTIF($C$2:C17, C17) = 1, 1, 0)) -> 0 | N17: Accessories | O17: =AVERAGEIF(Table4[Category], N17, Table4[Sales]) -> 4821.8627 | Q17: Headphones | R17: =SUMIF(Table4[Product], Q17, Table4[Sales]) -> 660100
A18: 1926 | B18: 15-04-2024 | C18: Sneha | D18: Pune | E18: Laptop | F18: Electronics | G18: 5 | H18: 50000 | I18: 0 | J18: =H18*(1-I18)*G18 -> 250000 | K18: =TEXT(Table4[OrderDate], "mmmm") -> April | L18: =IF(C18 = "", 0, IF(COUNTIF($C$2:C18, C18) = 1, 1, 0)) -> 0 | N18: Electronics | O18: =AVERAGEIF(Table4[Category], N18, Table4[Sales]) -> 79154.581 | Q18: Chair | R18: =SUMIF(Table4[Product], Q18, Table4[Sales]) -> 988050
A19: 1018 | B19: 26-02-2024 | C19: Karan | D19: Bangalore | E19: Monitor | F19: Electronics | G19: 1 | H19: 12000 | I19: 0 | J19: =H19*(1-I19)*G19 -> 12000 | K19: =TEXT(Table4[OrderDate], "mmmm") -> February | L19: =IF(C19 = "", 0, IF(COUNTIF($C$2:C19, C19) = 1, 1, 0)) -> 0 | N19: Furniture | O19: =AVERAGEIF(Table4[Category], N19, Table4[Sales]) -> 13435.776 | Q19: Table | R19: =SUMIF(Table4[Product], Q19, Table4[Sales]) -> 2129050
A20: 1981 | B20: 30-01-2024 | C20: Anjali | D20: Mumbai | E20: Laptop | F20: Electronics | G20: 5 | H20: 50000 | I20: 0 | J20: =H20*(1-I20)*G20 -> 250000 | K20: =TEXT(Table4[OrderDate], "mmmm") -> January | L20: =IF(C20 = "", 0, IF(COUNTIF($C$2:C20, C20) = 1, 1, 0)) -> 0
A21: 1256 | B21: 14-03-2024 | C21: Vikas | D21: Chennai | E21: Laptop | F21: Electronics | G21: 5 | H21: 50000 | I21: 0.05 | J21: =H21*(1-I21)*G21 -> 237500 | K21: =TEXT(Table4[OrderDate], "mmmm") -> March | L21: =IF(C21 = "", 0, IF(COUNTIF($C$2:C21, C21) = 1, 1, 0)) -> 1 | N21: Category | O21: Sales | P21: Contribution | R21: City | S21: Revenue Generated
A22: 1021 | B22: 10-08-2024 | C22: Rohit | D22: Hyderabad | E22: Headphones | F22: Accessories | G22: 1 | H22: 2000 | I22: 0.1 | J22: =H22*(1-I22)*G22 -> 1800 | K22: =TEXT(Table4[OrderDate], "mmmm") -> August | L22: =IF(C22 = "", 0, IF(COUNTIF($C$2:C22, C22) = 1, 1, 0)) -> 1 | N22: Electronics | O22: 40606300 | P22: =O22/SUM($O$22:$O$24)*100 -> 90.330618 | R22: Mumbai | S22: =SUMIF(Table4[City], R22, Table4[Sales]) -> 6073200
A23: 1022 | B23: 16-09-2024 | C23: Priya | D23: Jaipur | E23: Laptop | F23: Electronics | G23: 3 | H23: 50000 | I23: 0.05 | J23: =H23*(1-I23)*G23 -> 142500 | K23: =TEXT(Table4[OrderDate], "mmmm") -> September | L23: =IF(C23 = "", 0, IF(COUNTIF($C$2:C23, C23) = 1, 1, 0)) -> 0 | N23: Furniture | O23: 3117100 | P23: =O23/SUM($O$22:$O$24)*100 -> 6.9341351 | R23: Jaipur | S23: =SUMIF(Table4[City], R23, Table4[Sales]) -> 6282050
A24: 1023 | B24: 23-03-2024 | C24: Ravi | D24: Pune | E24: Chair | F24: Furniture | G24: 2 | H24: 3000 | I24: 0.1 | J24: =H24*(1-I24)*G24 -> 5400 | K24: =TEXT(Table4[OrderDate], "mmmm") -> March | L24: =IF(C24 = "", 0, IF(COUNTIF($C$2:C24, C24) = 1, 1, 0)) -> 0 | N24: Accessories | O24: 1229575 | P24: =O24/SUM($O$22:$O$24)*100 -> 2.7352472 | R24: Bangalore | S24: =SUMIF(Table4[City], R24, Table4[Sales]) -> 6509800
A25: 1024 | B25: 04-07-2024 | C25: Vikas | D25: Lucknow | E25: Monitor | F25: Electronics | G25: 1 | H25: 12000 | I25: 0 | J25: =H25*(1-I25)*G25 -> 12000 | K25: =TEXT(Table4[OrderDate], "mmmm") -> July | L25: =IF(C25 = "", 0, IF(COUNTIF($C$2:C25, C25) = 1, 1, 0)) -> 0 | R25: Pune | S25: =SUMIF(Table4[City], R25, Table4[Sales]) -> 4577350
A26: 1025 | B26: 13-02-2024 | C26: Simran | D26: Mumbai | E26: Laptop | F26: Electronics | G26: 2 | H26: 50000 | I26: 0 | J26: =H26*(1-I26)*G26 -> 100000 | K26: =TEXT(Table4[OrderDate], "mmmm") -> February | L26: =IF(C26 = "", 0, IF(COUNTIF($C$2:C26, C26) = 1, 1, 0)) -> 1 | R26: Chennai | S26: =SUMIF(Table4[City], R26, Table4[Sales]) -> 6085325
A27: 1026 | B27: 08-10-2024 | C27: Rohit | D27: Jaipur | E27: Tablet | F27: Electronics | G27: 2 | H27: 30000 | I27: 0.15 | J27: =H27*(1-I27)*G27 -> 51000 | K27: =TEXT(Table4[OrderDate], "mmmm") -> October | L27: =IF(C27 = "", 0, IF(COUNTIF($C$2:C27, C27) = 1, 1, 0)) -> 0 | M27: City | N27: Revenue Generated | O27: Category | P27: Electronics | R27: Lucknow | S27: =SUMIF(Table4[City], R27, Table4[Sales]) -> 4591925
A28: 1027 | B28: 08-06-2024 | C28: Arjun | D28: Pune | E28: Keyboard | F28: Accessories | G28: 2 | H28: 1500 | I28: 0.05 | J28: =H28*(1-I28)*G28 -> 2850 | K28: =TEXT(Table4[OrderDate], "mmmm") -> June | L28: =IF(C28 = "", 0, IF(COUNTIF($C$2:C28, C28) = 1, 1, 0)) -> 0 | M28: Mumbai | N28: =SUMIFS(Table4[Sales], Table4[Category], $P$27,Table4[City], M28) -> 5563400 | R28: Hyderabad | S28: =SUMIF(Table4[City], R28, Table4[Sales]) -> 6270225
A29: 1470 | B29: 13-08-2024 | C29: Sneha | D29: Lucknow | E29: Laptop | F29: Electronics | G29: 5 | H29: 50000 | I29: 0.05 | J29: =H29*(1-I29)*G29 -> 237500 | K29: =TEXT(Table4[OrderDate], "mmmm") -> August | L29: =IF(C29 = "", 0, IF(COUNTIF($C$2:C29, C29) = 1, 1, 0)) -> 0 | M29: Jaipur | N29: =SUMIFS(Table4[Sales], Table4[Category], $P$27,Table4[City], M29) -> 5756800 | R29: Delhi | S29: =SUMIF(Table4[City], R29, Table4[Sales]) -> 4563100
A30: 1029 | B30: 28-10-2024 | C30: Sanjay | D30: Lucknow | E30: Phone | F30: Electronics | G30: 3 | H30: 20000 | I30: 0 | J30: =H30*(1-I30)*G30 -> 60000 | K30: =TEXT(Table4[OrderDate], "mmmm") -> October | L30: =IF(C30 = "", 0, IF(COUNTIF($C$2:C30, C30) = 1, 1, 0)) -> 0 | M30: Bangalore | N30: =SUMIFS(Table4[Sales], Table4[Category], $P$27,Table4[City], M30) -> 5902400
A31: 1030 | B31: 27-04-2024 | C31: Neha | D31: Delhi | E31: Laptop | F31: Electronics | G31: 1 | H31: 50000 | I31: 0 | J31: =H31*(1-I31)*G31 -> 50000 | K31: =TEXT(Table4[OrderDate], "mmmm") -> April | L31: =IF(C31 = "", 0, IF(COUNTIF($C$2:C31, C31) = 1, 1, 0)) -> 0 | M31: Pune | N31: =SUMIFS(Table4[Sales], Table4[Category], $P$27,Table4[City], M31) -> 3990100
A32: 1031 | B32: 22-05-2024 | C32: Simran | D32: Lucknow | E32: Headphones | F32: Accessories | G32: 1 | H32: 2000 | I32: 0.05 | J32: =H32*(1-I32)*G32 -> 1900 | K32: =TEXT(Table4[OrderDate], "mmmm") -> May | L32: =IF(C32 = "", 0, IF(COUNTIF($C$2:C32, C32) = 1, 1, 0)) -> 0 | M32: Chennai | N32: =SUMIFS(Table4[Sales], Table4[Category], $P$27,Table4[City], M32) -> 5694500
A33: 1715 | B33: 29-01-2024 | C33: Rohit | D33: Jaipur | E33: Laptop | F33: Electronics | G33: 5 | H33: 50000 | I33: 0.05 | J33: =H33*(1-I33)*G33 -> 237500 | K33: =TEXT(Table4[OrderDate], "mmmm") -> January | L33: =IF(C33 = "", 0, IF(COUNTIF($C$2:C33, C33) = 1, 1, 0)) -> 0 | M33: Lucknow | N33: =SUMIFS(Table4[Sales], Table4[Category], $P$27,Table4[City], M33) -> 4086500 | S33: Chair | T33: Headphones | U33: Keyboard | V33: Laptop | W33: Monitor | X33: Phone | Y33: Table | Z33: Tablet
A34: 1033 | B34: 03-12-2024 | C34: Kavya | D34: Pune | E34: Chair | F34: Furniture | G34: 1 | H34: 3000 | I34: 0 | J34: =H34*(1-I34)*G34 -> 3000 | K34: =TEXT(Table4[OrderDate], "mmmm") -> December | L34: =IF(C34 = "", 0, IF(COUNTIF($C$2:C34, C34) = 1, 1, 0)) -> 1 | M34: Hyderabad | N34: =SUMIFS(Table4[Sales], Table4[Category], $P$27,Table4[City], M34) -> 5494200 | R34: Bangalore | S34: 163950 | T34: 95500 | U34: 52200 | V34: 2640000 | W34: 659400 | X34: 1055000 | Y34: 295750 | Z34: 1548000
A35: 1034 | B35: 28-01-2024 | C35: Priya | D35: Delhi | E35: Keyboard | F35: Accessories | G35: 4 | H35: 1500 | I35: 0.15 | J35: =H35*(1-I35)*G35 -> 5100 | K35: =TEXT(Table4[OrderDate], "mmmm") -> January | L35: =IF(C35 = "", 0, IF(COUNTIF($C$2:C35, C35) = 1, 1, 0)) -> 0 | M35: Delhi | N35: =SUMIFS(Table4[Sales], Table4[Category], $P$27,Table4[City], M35) -> 4118400 | R35: Chennai | S35: 88650 | T35: 57700 | U35: 76125 | V35: 2347500 | W35: 318000 | X35: 1262000 | Y35: 168350 | Z35: 1767000
A36: 1035 | B36: 07-05-2024 | C36: Anjali | D36: Lucknow | E36: Keyboard | F36: Accessories | G36: 3 | H36: 1500 | I36: 0 | J36: =H36*(1-I36)*G36 -> 4500 | K36: =TEXT(Table4[OrderDate], "mmmm") -> May | L36: =IF(C36 = "", 0, IF(COUNTIF($C$2:C36, C36) = 1, 1, 0)) -> 0 | R36: Delhi | S36: 140400 | T36: 67800 | U36: 61500 | V36: 1920000 | W36: 305400 | X36: 897000 | Y36: 175000 | Z36: 996000
A37: 1036 | B37: 03-04-2024 | C37: Pooja | D37: Hyderabad | E37: Monitor | F37: Electronics | G37: 2 | H37: 12000 | I37: 0.15 | J37: =H37*(1-I37)*G37 -> 20400 | K37: =TEXT(Table4[OrderDate], "mmmm") -> April | L37: =IF(C37 = "", 0, IF(COUNTIF($C$2:C37, C37) = 1, 1, 0)) -> 0 | M37: Bangalore | N37: 5902400 | R37: Hyderabad | S37: 166650 | T37: 111000 | U37: 127725 | V37: 2692500 | W37: 460200 | X37: 888000 | Y37: 370650 | Z37: 1453500
A38: 1037 | B38: 08-10-2024 | C38: Priya | D38: Delhi | E38: Chair | F38: Furniture | G38: 1 | H38: 3000 | I38: 0.15 | J38: =H38*(1-I38)*G38 -> 2550 | K38: =TEXT(Table4[OrderDate], "mmmm") -> October | L38: =IF(C38 = "", 0, IF(COUNTIF($C$2:C38, C38) = 1, 1, 0)) -> 0 | M38: Jaipur | N38: 5756800 | R38: Jaipur | S38: 105600 | T38: 81900 | U38: 64050 | V38: 2442500 | W38: 742800 | X38: 830000 | Y38: 273700 | Z38: 1741500
A39: 1038 | B39: 26-03-2024 | C39: Kavya | D39: Hyderabad | E39: Laptop | F39: Electronics | G39: 1 | H39: 50000 | I39: 0.05 | J39: =H39*(1-I39)*G39 -> 47500 | K39: =TEXT(Table4[OrderDate], "mmmm") -> March | L39: =IF(C39 = "", 0, IF(COUNTIF($C$2:C39, C39) = 1, 1, 0)) -> 0 | M39: Chennai | N39: 5694500 | R39: Lucknow | S39: 92850 | T39: 62900 | U39: 82275 | V39: 915000 | W39: 888000 | X39: 992000 | Y39: 267400 | Z39: 1291500
A40: 1039 | B40: 31-01-2024 | C40: Rohit | D40: Chennai | E40: Monitor | F40: Electronics | G40: 2 | H40: 12000 | I40: 0.15 | J40: =H40*(1-I40)*G40 -> 20400 | K40: =TEXT(Table4[OrderDate], "mmmm") -> January | L40: =IF(C40 = "", 0, IF(COUNTIF($C$2:C40, C40) = 1, 1, 0)) -> 0 | M40: Mumbai | N40: 5563400 | R40: Mumbai | S40: 116250 | T40: 79300 | U40: 40200 | V40: 2742500 | W40: 554400 | X40: 951000 | Y40: 274050 | Z40: 1315500
...

Sheet Analysis
A1: Total Revenue Generated | C1: =SUM(Dateset!J2:J1001) -> 44952975
A2: Total Order Count | C2: =COUNTA(Dateset!A2:A1001) -> 1000
G3: City | H3: Total Revenue
A4: Phone | B4: =SUMIF(Table4[Product], Analysis!A4, Table4[Quantity]) -> 427 | D4: Electronics | E4: =SUMIF(Table4[Category], Analysis!D4, Table4[Sales]) -> 40606300 | G4: Mumbai | H4: =SUMIF(Table4[City], Analysis!G4, Table4[Sales]) -> 6073200
A5: Keyboard | B5: =SUMIF(Table4[Product], Analysis!A5, Table4[Quantity]) -> 410 | G5: Jaipur | H5: =SUMIF(Table4[City], Analysis!G5, Table4[Sales]) -> 6282050
A6: Tablet | B6: =SUMIF(Table4[Product], Analysis!A6, Table4[Quantity]) -> 404 | G6: Bangalore | H6: =SUMIF(Table4[City], Analysis!G6, Table4[Sales]) -> 6509800
A7: Laptop | B7: =SUMIF(Table4[Product], Analysis!A7, Table4[Quantity]) -> 378 | G7: Pune | H7: =SUMIF(Table4[City], Analysis!G7, Table4[Sales]) -> 4577350
A8: Monitor | B8: =SUMIF(Table4[Product], Analysis!A8, Table4[Quantity]) -> 370 | G8: Chennai | H8: =SUMIF(Table4[City], Analysis!G8, Table4[Sales]) -> 6085325
A9: Headphones | B9: =SUMIF(Table4[Product], Analysis!A9, Table4[Quantity]) -> 359 | G9: Lucknow | H9: =SUMIF(Table4[City], Analysis!G9, Table4[Sales]) -> 4591925
A10: Chair | B10: =SUMIF(Table4[Product], Analysis!A10, Table4[Quantity]) -> 357 | G10: Hyderabad | H10: =SUMIF(Table4[City], Analysis!G10, Table4[Sales]) -> 6270225
A11: Table | B11: =SUMIF(Table4[Product], Analysis!A11, Table4[Quantity]) -> 329 | G11: Delhi | H11: =SUMIF(Table4[City], Analysis!G11, Table4[Sales]) -> 4563100
B13: Chair | C13: Headphones | D13: Keyboard | E13: Laptop | F13: Monitor | G13: Phone | H13: Table | I13: Tablet | J13: Special Block
A14: Bangalore | B14: =SUMIFS(Table4[[Sales]:[Sales]], Table4[[City]:[City]], Analysis!$A14, Table4[[Product]:[Product]], Analysis!B$13) -> 163950 | C14: =SUMIFS(Table4[[Sales]:[Sales]], Table4[[City]:[City]], Analysis!$A14, Table4[[Product]:[Product]], Analysis!C$13) -> 95500 | D14: =SUMIFS(Table4[[Sales]:[Sales]], Table4[[City]:[City]], Analysis!$A14, Table4[[Product]:[Product]], Analysis!D$13) -> 52200 | E14: =SUMIFS(Table4[[Sales]:[Sales]], Table4[[City]:[City]], Analysis!$A14, Table4[[Product]:[Product]], Analysis!E$13) -> 2640000 | F14: =SUMIFS(Table4[[Sales]:[Sales]], Table4[[City]:[City]], Analysis!$A14, Table4[[Product]:[Product]], Analysis!F$13) -> 659400 | G14: =SUMIFS(Table4[[Sales]:[Sales]], Table4[[City]:[City]], Analysis!$A14, Table4[[Product]:[Product]], Analysis!G$13) -> 1055000 | H14: =SUMIFS(Table4[[Sales]:[Sales]], Table4[[City]:[City]], Analysis!$A14, Table4[[Product]:[Product]], Analysis!H$13) -> 295750 | I14: =SUMIFS(Table4[[Sales]:[Sales]], Table4[[City]:[City]], Analysis!$A14, Table4[[Product]:[Product]], Analysis!I$13) -> 1548000 | J14: =MAX(B14:I14) -> 2640000 | K14: =MATCH(J14, B14:I14, 0) -> 4 | L14: =INDEX($B$13:$I$13, 1, K14) -> Laptop
A15: Chennai | B15: =SUMIFS(Table4[[Sales]:[Sales]], Table4[[City]:[City]], Analysis!$A15, Table4[[Product]:[Product]], Analysis!B$13) -> 88650 | C15: =SUMIFS(Table4[[Sales]:[Sales]], Table4[[City]:[City]], Analysis!$A15, Table4[[Product]:[Product]], Analysis!C$13) -> 57700 | D15: =SUMIFS(Table4[[Sales]:[Sales]], Table4[[City]:[City]], Analysis!$A15, Table4[[Product]:[Product]], Analysis!D$13) -> 76125 | E15: =SUMIFS(Table4[[Sales]:[Sales]], Table4[[City]:[City]], Analysis!$A15, Table4[[Product]:[Product]], Analysis!E$13) -> 2347500 | F15: =SUMIFS(Table4[[Sales]:[Sales]], Table4[[City]:[City]], Analysis!$A15, Table4[[Product]:[Product]], Analysis!F$13) -> 318000 | G15: =SUMIFS(Table4[[Sales]:[Sales]], Table4[[City]:[City]], Analysis!$A15, Table4[[Product]:[Product]], Analysis!G$13) -> 1262000 | H15: =SUMIFS(Table4[[Sales]:[Sales]], Table4[[City]:[City]], Analysis!$A15, Table4[[Product]:[Product]], Analysis!H$13) -> 168350 | I15: =SUMIFS(Table4[[Sales]:[Sales]], Table4[[City]:[City]], Analysis!$A15, Table4[[Product]:[Product]], Analysis!I$13) -> 1767000 | J15: =MAX(B15:I15) -> 2347500 | K15: =MATCH(J15, B15:I15, 0) -> 4 | L15: =INDEX($B$13:$I$13, 1, K15) -> Laptop
A16: Delhi | B16: =SUMIFS(Table4[[Sales]:[Sales]], Table4[[City]:[City]], Analysis!$A16, Table4[[Product]:[Product]], Analysis!B$13) -> 140400 | C16: =SUMIFS(Table4[[Sales]:[Sales]], Table4[[City]:[City]], Analysis!$A16, Table4[[Product]:[Product]], Analysis!C$13) -> 67800 | D16: =SUMIFS(Table4[[Sales]:[Sales]], Table4[[City]:[City]], Analysis!$A16, Table4[[Product]:[Product]], Analysis!D$13) -> 61500 | E16: =SUMIFS(Table4[[Sales]:[Sales]], Table4[[City]:[City]], Analysis!$A16, Table4[[Product]:[Product]], Analysis!E$13) -> 1920000 | F16: =SUMIFS(Table4[[Sales]:[Sales]], Table4[[City]:[City]], Analysis!$A16, Table4[[Product]:[Product]], Analysis!F$13) -> 305400 | G16: =SUMIFS(Table4[[Sales]:[Sales]], Table4[[City]:[City]], Analysis!$A16, Table4[[Product]:[Product]], Analysis!G$13) -> 897000 | H16: =SUMIFS(Table4[[Sales]:[Sales]], Table4[[City]:[City]], Analysis!$A16, Table4[[Product]:[Product]], Analysis!H$13) -> 175000 | I16: =SUMIFS(Table4[[Sales]:[Sales]], Table4[[City]:[City]], Analysis!$A16, Table4[[Product]:[Product]], Analysis!I$13) -> 996000 | J16: =MAX(B16:I16) -> 1920000 | K16: =MATCH(J16, B16:I16, 0) -> 4 | L16: =INDEX($B$13:$I$13, 1, K16) -> Laptop
A17: Hyderabad | B17: =SUMIFS(Table4[[Sales]:[Sales]], Table4[[City]:[City]], Analysis!$A17, Table4[[Product]:[Product]], Analysis!B$13) -> 166650 | C17: =SUMIFS(Table4[[Sales]:[Sales]], Table4[[City]:[City]], Analysis!$A17, Table4[[Product]:[Product]], Analysis!C$13) -> 111000 | D17: =SUMIFS(Table4[[Sales]:[Sales]], Table4[[City]:[City]], Analysis!$A17, Table4[[Product]:[Product]], Analysis!D$13) -> 127725 | E17: =SUMIFS(Table4[[Sales]:[Sales]], Table4[[City]:[City]], Analysis!$A17, Table4[[Product]:[Product]], Analysis!E$13) -> 2692500 | F17: =SUMIFS(Table4[[Sales]:[Sales]], Table4[[City]:[City]], Analysis!$A17, Table4[[Product]:[Product]], Analysis!F$13) -> 460200 | G17: =SUMIFS(Table4[[Sales]:[Sales]], Table4[[City]:[City]], Analysis!$A17, Table4[[Product]:[Product]], Analysis!G$13) -> 888000 | H17: =SUMIFS(Table4[[Sales]:[Sales]], Table4[[City]:[City]], Analysis!$A17, Table4[[Product]:[Product]], Analysis!H$13) -> 370650 | I17: =SUMIFS(Table4[[Sales]:[Sales]], Table4[[City]:[City]], Analysis!$A17, Table4[[Product]:[Product]], Analysis!I$13) -> 1453500 | J17: =MAX(B17:I17) -> 2692500 | K17: =MATCH(J17, B17:I17, 0) -> 4 | L17: =INDEX($B$13:$I$13, 1, K17) -> Laptop
A18: Jaipur | B18: =SUMIFS(Table4[[Sales]:[Sales]], Table4[[City]:[City]], Analysis!$A18, Table4[[Product]:[Product]], Analysis!B$13) -> 105600 | C18: =SUMIFS(Table4[[Sales]:[Sales]], Table4[[City]:[City]], Analysis!$A18, Table4[[Product]:[Product]], Analysis!C$13) -> 81900 | D18: =SUMIFS(Table4[[Sales]:[Sales]], Table4[[City]:[City]], Analysis!$A18, Table4[[Product]:[Product]], Analysis!D$13) -> 64050 | E18: =SUMIFS(Table4[[Sales]:[Sales]], Table4[[City]:[City]], Analysis!$A18, Table4[[Product]:[Product]], Analysis!E$13) -> 2442500 | F18: =SUMIFS(Table4[[Sales]:[Sales]], Table4[[City]:[City]], Analysis!$A18, Table4[[Product]:[Product]], Analysis!F$13) -> 742800 | G18: =SUMIFS(Table4[[Sales]:[Sales]], Table4[[City]:[City]], Analysis!$A18, Table4[[Product]:[Product]], Analysis!G$13) -> 830000 | H18: =SUMIFS(Table4[[Sales]:[Sales]], Table4[[City]:[City]], Analysis!$A18, Table4[[Product]:[Product]], Analysis!H$13) -> 273700 | I18: =SUMIFS(Table4[[Sales]:[Sales]], Table4[[City]:[City]], Analysis!$A18, Table4[[Product]:[Product]], Analysis!I$13) -> 1741500 | J18: =MAX(B18:I18) -> 2442500 | K18: =MATCH(J18, B18:I18, 0) -> 4 | L18: =INDEX($B$13:$I$13, 1, K18) -> Laptop
A19: Lucknow | B19: =SUMIFS(Table4[[Sales]:[Sales]], Table4[[City]:[City]], Analysis!$A19, Table4[[Product]:[Product]], Analysis!B$13) -> 92850 | C19: =SUMIFS(Table4[[Sales]:[Sales]], Table4[[City]:[City]], Analysis!$A19, Table4[[Product]:[Product]], Analysis!C$13) -> 62900 | D19: =SUMIFS(Table4[[Sales]:[Sales]], Table4[[City]:[City]], Analysis!$A19, Table4[[Product]:[Product]], Analysis!D$13) -> 82275 | E19: =SUMIFS(Table4[[Sales]:[Sales]], Table4[[City]:[City]], Analysis!$A19, Table4[[Product]:[Product]], Analysis!E$13) -> 915000 | F19: =SUMIFS(Table4[[Sales]:[Sales]], Table4[[City]:[City]], Analysis!$A19, Table4[[Product]:[Product]], Analysis!F$13) -> 888000 | G19: =SUMIFS(Table4[[Sales]:[Sales]], Table4[[City]:[City]], Analysis!$A19, Table4[[Product]:[Product]], Analysis!G$13) -> 992000 | H19: =SUMIFS(Table4[[Sales]:[Sales]], Table4[[City]:[City]], Analysis!$A19, Table4[[Product]:[Product]], Analysis!H$13) -> 267400 | I19: =SUMIFS(Table4[[Sales]:[Sales]], Table4[[City]:[City]], Analysis!$A19, Table4[[Product]:[Product]], Analysis!I$13) -> 1291500 | J19: =MAX(B19:I19) -> 1291500 | K19: =MATCH(J19, B19:I19, 0) -> 8 | L19: =INDEX($B$13:$I$13, 1, K19) -> Tablet
A20: Mumbai | B20: =SUMIFS(Table4[[Sales]:[Sales]], Table4[[City]:[City]], Analysis!$A20, Table4[[Product]:[Product]], Analysis!B$13) -> 116250 | C20: =SUMIFS(Table4[[Sales]:[Sales]], Table4[[City]:[City]], Analysis!$A20, Table4[[Product]:[Product]], Analysis!C$13) -> 79300 | D20: =SUMIFS(Table4[[Sales]:[Sales]], Table4[[City]:[City]], Analysis!$A20, Table4[[Product]:[Product]], Analysis!D$13) -> 40200 | E20: =SUMIFS(Table4[[Sales]:[Sales]], Table4[[City]:[City]], Analysis!$A20, Table4[[Product]:[Product]], Analysis!E$13) -> 2742500 | F20: =SUMIFS(Table4[[Sales]:[Sales]], Table4[[City]:[City]], Analysis!$A20, Table4[[Product]:[Product]], Analysis!F$13) -> 554400 | G20: =SUMIFS(Table4[[Sales]:[Sales]], Table4[[City]:[City]], Analysis!$A20, Table4[[Product]:[Product]], Analysis!G$13) -> 951000 | H20: =SUMIFS(Table4[[Sales]:[Sales]], Table4[[City]:[City]], Analysis!$A20, Table4[[Product]:[Product]], Analysis!H$13) -> 274050 | I20: =SUMIFS(Table4[[Sales]:[Sales]], Table4[[City]:[City]], Analysis!$A20, Table4[[Product]:[Product]], Analysis!I$13) -> 1315500 | J20: =MAX(B20:I20) -> 2742500 | K20: =MATCH(J20, B20:I20, 0) -> 4 | L20: =INDEX($B$13:$I$13, 1, K20) -> Laptop
A21: Pune | B21: =SUMIFS(Table4[[Sales]:[Sales]], Table4[[City]:[City]], Analysis!$A21, Table4[[Product]:[Product]], Analysis!B$13) -> 113700 | C21: =SUMIFS(Table4[[Sales]:[Sales]], Table4[[City]:[City]], Analysis!$A21, Table4[[Product]:[Product]], Analysis!C$13) -> 104000 | D21: =SUMIFS(Table4[[Sales]:[Sales]], Table4[[City]:[City]], Analysis!$A21, Table4[[Product]:[Product]], Analysis!D$13) -> 65400 | E21: =SUMIFS(Table4[[Sales]:[Sales]], Table4[[City]:[City]], Analysis!$A21, Table4[[Product]:[Product]], Analysis!E$13) -> 1747500 | F21: =SUMIFS(Table4[[Sales]:[Sales]], Table4[[City]:[City]], Analysis!$A21, Table4[[Product]:[Product]], Analysis!F$13) -> 153600 | G21: =SUMIFS(Table4[[Sales]:[Sales]], Table4[[City]:[City]], Analysis!$A21, Table4[[Product]:[Product]], Analysis!G$13) -> 1057000 | H21: =SUMIFS(Table4[[Sales]:[Sales]], Table4[[City]:[City]], Analysis!$A21, Table4[[Product]:[Product]], Analysis!H$13) -> 304150 | I21: =SUMIFS(Table4[[Sales]:[Sales]], Table4[[City]:[City]], Analysis!$A21, Table4[[Product]:[Product]], Analysis!I$13) -> 1032000 | J21: =MAX(B21:I21) -> 1747500 | K21: =MATCH(J21, B21:I21, 0) -> 4 | L21: =INDEX($B$13:$I$13, 1, K21) -> Laptop
J22: =MAX(J14:J21) -> 2742500 | K22: =MATCH(J22, J14:J21, 0) -> 7 | L22: =INDEX(A14:A21, K22, 0) -> Mumbai | M22: =INDEX(L14:L21, K22, 1) -> Laptop

Sheet Pivot Table
A3: Row Labels | B3: Sum of Sales | E3: Row Labels | F3: Sum of Sales | H3: Row Labels | I3: Sum of Sales
A4: Electronics | B4: 40606300 | E4: Delhi | F4: 4563100 | H4: Laptop | I4: 17447500
A5: Furniture | B5: 3117100 | E5: Pune | F5: 4577350 | H5: Monitor | I5: 4081800
A6: Accessories | B6: 1229575 | E6: Lucknow | F6: 4591925 | H6: Phone | I6: 7932000
A7: Grand Total | B7: 44952975 | E7: Mumbai | F7: 6073200 | H7: Table | I7: 2129050
E8: Chennai | F8: 6085325 | H8: Tablet | I8: 11145000
E9: Hyderabad | F9: 6270225 | H9: Grand Total | I9: 42735350
E10: Jaipur | F10: 6282050
E11: Bangalore | F11: 6509800
E12: Grand Total | F12: 44952975
A13: Row Labels | B13: Sum of Quantity
A14: Electronics | B14: 1579
A15: Accessories | B15: 769
A16: Furniture | B16: 686
A17: Grand Total | B17: 3034 | E17: Row Labels | F17: Average of Sales | H17: Row Labels | I17: Sum of Sales
E18: Electronics | F18: 79154.581 | H18: Electronics | I18: 0.90330618
E19: Furniture | F19: 13435.776 | H19: Furniture | I19: 0.069341351
E20: Accessories | F20: 4821.8627 | H20: Accessories | I20: 0.027352472
E21: Grand Total | F21: 44952.975 | H21: Grand Total | I21: 1
E25: Category | F25: Electronics | H25: Row Labels | I25: Sum of Sales
H26: Vikas | I26: 3896950
E27: Row Labels | F27: Sum of Sales | H27: Anjali | I27: 3557025
E28: Bangalore | F28: 5902400 | H28: Sneha | I28: 3471950
E29: Jaipur | F29: 5756800 | H29: Kavya | I29: 3392350
E30: Chennai | F30: 5694500 | H30: Neha | I30: 3237375
E31: Mumbai | F31: 5563400 | H31: Priya | I31: 3195650
E32: Hyderabad | F32: 5494200 | H32: Manish | I32: 3030200
E33: Delhi | F33: 4118400 | H33: Karan | I33: 2746525
E34: Lucknow | F34: 4086500 | H34: Simran | I34: 2686075
E35: Pune | F35: 3990100 | H35: Aman | I35: 2598200
E36: Grand Total | F36: 40606300 | H36: Sanjay | I36: 2409400
H37: Arjun | I37: 2316525
H38: Ravi | I38: 2232750
H39: Rohit | I39: 2189775
H40: Pooja | I40: 2153400
H41: Rahul | I41: 1838825
D42: Category | E42: Electronics | H42: Grand Total | I42: 44952975
A44: Row Labels | B44: Sum of Sales | D44: Row Labels | E44: Sum of Sales
A45: Laptop | B45: 17447500 | D45: December | E45: 4306400 | G45: Row Labels | H45: Sum of Sales | K45: Values
A46: Tablet | B46: 11145000 | D46: April | E46: 3955800 | G46: Bangalore | H46: 0.14481355 | J46: Row Labels | K46: Sum of Sales | L46: Sum of Quantity
...

Sheet Pivot For Dashboard
B2: Row Labels | C2: Sum of Sales | E2: Row Labels | F2: Sum of Sales | H2: Row Labels | I2: Sum of Sales | K2: ="Total Sales " & "₹" & SUM(Table4[Sales]) -> Total Sales ₹44952975
B3: January | C3: 3708600 | E3: Laptop | F3: 17447500 | H3: Accessories | I3: 1229575 | K3: ="Total Orders " & COUNTA(Table4[OrderID]) -> Total Orders 1000
B4: February | C4: 2721100 | E4: Tablet | F4: 11145000 | H4: Electronics | I4: 40606300 | K4: ="Total Quantity " & SUM(Table4[Quantity]) -> Total Quantity 3034
B5: March | C5: 4317475 | E5: Phone | F5: 7932000 | H5: Furniture | I5: 3117100 | K5: ="Average Discount " & ROUND(AVERAGE(Table4[Discount])*100, 2) & "%" -> Average Discount 7.72%
B6: April | C6: 4268200 | E6: Monitor | F6: 4081800 | H6: Grand Total | I6: 44952975 | K6: ="Unique Customers " & SUM(Table4[Distinct Count]) -> Unique Customers 16
B7: May | C7: 3667175 | E7: Table | F7: 2129050
B8: June | C8: 4096650 | E8: Chair | F8: 988050
B9: July | C9: 3421650 | E9: Headphones | F9: 660100
B10: August | C10: 3651050 | E10: Keyboard | F10: 569475
B11: September | C11: 3630525 | E11: Grand Total | F11: 44952975
B12: October | C12: 3021825
B13: November | C13: 3667675
B14: December | C14: 4781050
B15: Grand Total | C15: 44952975

Sheet DashBoard
